Workbook

Sheet TestCases
A1: Case ID | B1: Scenario | C1: Actual Label | D1: Expected Attack Type | E1: Source IP | F1: Function Code | G1: Machine Register | H1: Requested Value | I1: Signature Mode | J1: Repeat Count | K1: Seconds Since Last Settle | L1: Current TANK_PRESSURE | M1: Current CONVEYOR_SPEED | N1: Current COOLING_VALVE | O1: Current HEATER_TEMP | P1: Current FEED_PUMP | Q1: Current RELIEF_VALVE | R1: Current AIR_COMPRESSOR | S1: Current MIXER_SPEED | T1: Current COOLANT_FLOW | U1: Current EXHAUST_FAN | V1: Pending Setpoints (JSON) | W1: Description | X1: Cyber Verdict | Y1: Cyber Reason | Z1: Physical Verdict | AA1: Physical Reason | AB1: Final Decision | AC1: Orchestrator Reason | AD1: Detected Attack Type | AE1: Predicted Label | AF1: Outcome
A2: N01 | B2: Operator pressure step | C2: NORMAL | D2: - | E2: 127.0.0.1 | F2: 16 | G2: TANK_PRESSURE | H2: 51 | I2: valid | J2: 1 | K2: 12 | L2: 50 | M2: 0 | N2: 45 | O2: 60 | P2: 40 | Q2: 45 | R2: 1500 | S2: 100 | T2: 80 | U2: 50 | W2: 50 -> 51 PSI signed operator step | X2: PASS | Y2: OK | Z2: PASS | AA2: OK | AB2: PASS | AC2: OK | AD2: - | AE2: NORMAL | AF2: =IF(OR(AE2="",C2=""),"",IF(C2="ATTACK",IF(AE2="ATTACK","TP","FN"),IF(AE2="ATTACK","FP","TN")))
A3: N02 | B3: Operator conveyor step | C3: NORMAL | D3: - | E3: 127.0.0.1 | F3: 16 | G3: CONVEYOR_SPEED | H3: 2 | I3: valid | J3: 1 | K3: 12 | L3: 50 | M3: 0 | N3: 45 | O3: 60 | P3: 40 | Q3: 45 | R3: 1500 | S3: 100 | T3: 80 | U3: 50 | W3: 0 -> 2 RPM | X3: PASS | Y3: OK | Z3: PASS | AA3: OK | AB3: PASS | AC3: OK | AD3: - | AE3: NORMAL | AF3: =IF(OR(AE3="",C3=""),"",IF(C3="ATTACK",IF(AE3="ATTACK","TP","FN"),IF(AE3="ATTACK","FP","TN")))
A4: N03 | B4: Operator cooling step | C4: NORMAL | D4: - | E4: 127.0.0.1 | F4: 16 | G4: COOLING_VALVE | H4: 46 | I4: valid | J4: 1 | K4: 12 | L4: 50 | M4: 0 | N4: 45 | O4: 60 | P4: 40 | Q4: 45 | R4: 1500 | S4: 100 | T4: 80 | U4: 50 | W4: 45 -> 46 deg | X4: PASS | Y4: OK | Z4: PASS | AA4: OK | AB4: PASS | AC4: OK | AD4: - | AE4: NORMAL | AF4: =IF(OR(AE4="",C4=""),"",IF(C4="ATTACK",IF(AE4="ATTACK","TP","FN"),IF(AE4="ATTACK","FP","TN")))
A5: N04 | B5: Operator heater step | C5: NORMAL | D5: - | E5: 127.0.0.1 | F5: 16 | G5: HEATER_TEMP | H5: 61 | I5: valid | J5: 1 | K5: 12 | L5: 50 | M5: 0 | N5: 45 | O5: 60 | P5: 40 | Q5: 45 | R5: 1500 | S5: 100 | T5: 80 | U5: 50 | W5: 60 -> 61 C | X5: PASS | Y5: OK | Z5: PASS | AA5: OK | AB5: PASS | AC5: OK | AD5: - | AE5: NORMAL | AF5: =IF(OR(AE5="",C5=""),"",IF(C5="ATTACK",IF(AE5="ATTACK","TP","FN"),IF(AE5="ATTACK","FP","TN")))
A6: N05 | B6: Operator feed pump step | C6: NORMAL | D6: - | E6: 127.0.0.1 | F6: 16 | G6: FEED_PUMP | H6: 41 | I6: valid | J6: 1 | K6: 12 | L6: 50 | M6: 0 | N6: 45 | O6: 60 | P6: 40 | Q6: 45 | R6: 1500 | S6: 100 | T6: 80 | U6: 50 | W6: 40 -> 41 % | X6: PASS | Y6: OK | Z6: PASS | AA6: OK | AB6: PASS | AC6: OK | AD6: - | AE6: NORMAL | AF6: =IF(OR(AE6="",C6=""),"",IF(C6="ATTACK",IF(AE6="ATTACK","TP","FN"),IF(AE6="ATTACK","FP","TN")))
A7: N06 | B7: Operator relief valve step | C7: NORMAL | D7: - | E7: 127.0.0.1 | F7: 16 | G7: RELIEF_VALVE | H7: 46 | I7: valid | J7: 1 | K7: 12 | L7: 50 | M7: 0 | N7: 45 | O7: 60 | P7: 40 | Q7: 45 | R7: 1500 | S7: 100 | T7: 80 | U7: 50 | W7: 45 -> 46 deg | X7: PASS | Y7: OK | Z7: PASS | AA7: OK | AB7: PASS | AC7: OK | AD7: - | AE7: NORMAL | AF7: =IF(OR(AE7="",C7=""),"",IF(C7="ATTACK",IF(AE7="ATTACK","TP","FN"),IF(AE7="ATTACK","FP","TN")))
A8: N07 | B8: Heater high with cooling open | C8: NORMAL | D8: - | E8: 127.0.0.1 | F8: 16 | G8: HEATER_TEMP | H8: 112 | I8: valid | J8: 1 | K8: 10 | L8: 50 | M8: 0 | N8: 60 | O8: 102 | P8: 40 | Q8: 45 | R8: 1500 | S8: 100 | T8: 80 | U8: 50 | W8: Legitimate multi-register combination: hot reactor but adequate cooling | X8: PASS | Y8: OK | Z8: PASS | AA8: OK | AB8: PASS | AC8: OK | AD8: - | AE8: NORMAL | AF8: =IF(OR(AE8="",C8=""),"",IF(C8="ATTACK",IF(AE8="ATTACK","TP","FN"),IF(AE8="ATTACK","FP","TN")))
A9: N08 | B9: Pump high with relief open | C9: NORMAL | D9: - | E9: 127.0.0.1 | F9: 16 | G9: FEED_PUMP | H9: 75 | I9: valid | J9: 1 | K9: 10 | L9: 50 | M9: 0 | N9: 45 | O9: 60 | P9: 65 | Q9: 50 | R9: 1500 | S9: 100 | T9: 80 | U9: 50 | W9: Legitimate multi-register combination: high feed with relief path open | X9: PASS | Y9: OK | Z9: PASS | AA9: OK | AB9: PASS | AC9: OK | AD9: - | AE9: NORMAL | AF9: =IF(OR(AE9="",C9=""),"",IF(C9="ATTACK",IF(AE9="ATTACK","TP","FN"),IF(AE9="ATTACK","FP","TN")))
A10: N09 | B10: Relief nearly closed at low feed | C10: NORMAL | D10: - | E10: 127.0.0.1 | F10: 16 | G10: RELIEF_VALVE | H10: 12 | I10: valid | J10: 1 | K10: 10 | L10: 50 | M10: 0 | N10: 45 | O10: 60 | P10: 40 | Q10: 45 | R10: 1500 | S10: 100 | T10: 80 | U10: 50 | W10: Relief low is safe because feed pump is low | X10: PASS | Y10: OK | Z10: PASS | AA10: OK | AB10: PASS | AC10: OK | AD10: - | AE10: NORMAL | AF10: =IF(OR(AE10="",C10=""),"",IF(C10="ATTACK",IF(AE10="ATTACK","TP","FN"),IF(AE10="ATTACK","FP","TN")))
A11: N10 | B11: Cooling low at moderate heat | C11: NORMAL | D11: - | E11: 127.0.0.1 | F11: 16 | G11: COOLING_VALVE | H11: 20 | I11: valid | J11: 1 | K11: 10 | L11: 50 | M11: 0 | N11: 30 | O11: 80 | P11: 40 | Q11: 45 | R11: 1500 | S11: 100 | T11: 80 | U11: 50 | W11: Cooling low is safe because heater setpoint is moderate | X11: PASS | Y11: OK | Z11: PASS | AA11: OK | AB11: PASS | AC11: OK | AD11: - | AE11: NORMAL | AF11: =IF(OR(AE11="",C11=""),"",IF(C11="ATTACK",IF(AE11="ATTACK","TP","FN"),IF(AE11="ATTACK","FP","TN")))
A12: N11 | B12: Pressure up with warm heater | C12: NORMAL | D12: - | E12: 127.0.0.1 | F12: 16 | G12: TANK_PRESSURE | H12: 86 | I12: valid | J12: 1 | K12: 5 | L12: 80 | M12: 0 | N12: 45 | O12: 110 | P12: 40 | Q12: 45 | R12: 1500 | S12: 100 | T12: 80 | U12: 50 | W12: Below HOT_PRESSURIZED_VESSEL heater threshold (125 C) | X12: PASS | Y12: OK | Z12: PASS | AA12: OK | AB12: PASS | AC12: OK | AD12: - | AE12: NORMAL | AF12: =IF(OR(AE12="",C12=""),"",IF(C12="ATTACK",IF(AE12="ATTACK","TP","FN"),IF(AE12="ATTACK","FP","TN")))
A13: N12 | B13: Corrective move out of unsafe state | C13: NORMAL | D13: - | E13: 127.0.0.1 | F13: 16 | G13: FEED_PUMP | H13: 75 | I13: valid | J13: 1 | K13: 10 | L13: 50 | M13: 0 | N13: 45 | O13: 60 | P13: 80 | Q13: 10 | R13: 1500 | S13: 100 | T13: 80 | U13: 50 | W13: Plant already in OVERPRESSURE combination; operator reduces pump | X13: PASS | Y13: OK | Z13: PASS | AA13: OK | AB13: PASS | AC13: OK | AD13: - | AE13: NORMAL | AF13: =IF(OR(AE13="",C13=""),"",IF(C13="ATTACK",IF(AE13="ATTACK","TP","FN"),IF(AE13="ATTACK","FP","TN")))
... A15: N14 | B15: Second trusted SCADA host | C15: NORMAL | D15: - | E15: 192.168.1.10 | F15: 16 | G15: COOLING_VALVE | H15: 46 | I15: valid | J15: 1 | K15: 12 | L15: 50 | M15: 0 | N15: 45 | O15: 60 | P15: 40 | Q15: 45 | R15: 1500 | S15: 100 | T15: 80 | U15: 50 | W15: Signed command from the other whitelisted SCADA address | X15: PASS | Y15: OK | Z15: PASS | AA15: OK | AB15: PASS | AC15: OK | AD15: - | AE15: NORMAL | AF15: =IF(OR(AE15="",C15=""),"",IF(C15="ATTACK",IF(AE15="ATTACK","TP","FN"),IF(AE15="ATTACK","FP","TN")))
A16: N15 | B16: Pressure and heat both high but below limits | C16: NORMAL | D16: - | E16: 127.0.0.1 | F16: 16 | G16: HEATER_TEMP | H16: 124 | I16: valid | J16: 1 | K16: 10 | L16: 84 | M16: 0 | N16: 60 | O16: 115 | P16: 40 | Q16: 45 | R16: 1500 | S16: 100 | T16: 80 | U16: 50 | X16: PASS | Y16: OK | Z16: PASS | AA16: OK | AB16: PASS | AC16: OK | AD16: - | AE16: NORMAL | AF16: =IF(OR(AE16="",C16=""),"",IF(C16="ATTACK",IF(AE16="ATTACK","TP","FN"),IF(AE16="ATTACK","FP","TN")))
A17: N16 | B17: Fast conveyor, moderate pressure | C17: NORMAL | D17: - | E17: 127.0.0.1 | F17: 16 | G17: CONVEYOR_SPEED | H17: 110 | I17: valid | J17: 1 | K17: 5 | L17: 80 | M17: 100 | N17: 45 | O17: 60 | P17: 40 | Q17: 45 | R17: 1500 | S17: 100 | T17: 80 | U17: 50 | X17: PASS | Y17: OK | Z17: PASS | AA17: OK | AB17: PASS | AC17: OK | AD17: - | AE17: NORMAL | AF17: =IF(OR(AE17="",C17=""),"",IF(C17="ATTACK",IF(AE17="ATTACK","TP","FN"),IF(AE17="ATTACK","FP","TN")))
A18: N17 | B18: Cooling reduced at normal pressure | C18: NORMAL | D18: - | E18: 127.0.0.1 | F18: 16 | G18: COOLING_VALVE | H18: 44 | I18: valid | J18: 1 | K18: 5 | L18: 30 | M18: 0 | N18: 60 | O18: 60 | P18: 40 | Q18: 45 | R18: 1500 | S18: 100 | T18: 80 | U18: 50 | X18: PASS | Y18: OK | Z18: PASS | AA18: OK | AB18: PASS | AC18: OK | AD18: - | AE18: NORMAL | AF18: =IF(OR(AE18="",C18=""),"",IF(C18="ATTACK",IF(AE18="ATTACK","TP","FN"),IF(AE18="ATTACK","FP","TN")))
A19: N18 | B19: Emergency fast cooling open | C19: NORMAL | D19: - | E19: 127.0.0.1 | F19: 16 | G19: COOLING_VALVE | H19: 80 | I19: valid | J19: 1 | K19: 1 | L19: 50 | M19: 0 | N19: 45 | O19: 60 | P19: 40 | Q19: 45 | R19: 1500 | S19: 100 | T19: 80 | U19: 50 | W19: Legitimate emergency action faster than the valve ramp (edge case) | X19: PASS | Y19: OK | Z19: FAIL | AA19: RATE_OF_CHANGE_EXCEEDED:COOLING_VALVE Δ35.00 > max 5.50 in 1.000s | AB19: DROP | AC19: RATE_OF_CHANGE_EXCEEDED:COOLING_VALVE Δ35.00 > max 5.50 in 1.000s | AD19: Rate-of-Change Violation | AE19: ATTACK | AF19: =IF(OR(AE19="",C19=""),"",IF(C19="ATTACK",IF(AE19="ATTACK","TP","FN"),IF(AE19="ATTACK","FP","TN")))
A20: N19 | B20: Short operator burst | C20: NORMAL | D20: - | E20: 127.0.0.1 | F20: 16 | G20: RELIEF_VALVE | H20: 46 | I20: valid | J20: 3 | K20: 12 | L20: 50 | M20: 0 | N20: 45 | O20: 60 | P20: 40 | Q20: 45 | R20: 1500 | S20: 100 | T20: 80 | U20: 50 | W20: 3 quick legitimate adjustments (below 5 req/s) | X20: PASS | Y20: OK | Z20: PASS | AA20: OK | AB20: PASS | AC20: OK | AD20: - | AE20: NORMAL | AF20: =IF(OR(AE20="",C20=""),"",IF(C20="ATTACK",IF(AE20="ATTACK","TP","FN"),IF(AE20="ATTACK","FP","TN")))
A21: N20 | B21: Operator relief step | C21: NORMAL | D21: - | E21: 127.0.0.1 | F21: 16 | G21: RELIEF_VALVE | H21: 51 | I21: valid | J21: 1 | K21: 12 | L21: 50 | M21: 0 | N21: 45 | O21: 60 | P21: 40 | Q21: 50 | R21: 1500 | S21: 100 | T21: 80 | U21: 50 | X21: PASS | Y21: OK | Z21: PASS | AA21: OK | AB21: PASS | AC21: OK | AD21: - | AE21: NORMAL | AF21: =IF(OR(AE21="",C21=""),"",IF(C21="ATTACK",IF(AE21="ATTACK","TP","FN"),IF(AE21="ATTACK","FP","TN")))
A22: A01 | B22: Unsigned command | C22: ATTACK | D22: Missing HMAC (Unsigned Command) | E22: 127.0.0.1 | F22: 6 | G22: COOLING_VALVE | H22: 46 | I22: missing | J22: 1 | K22: 12 | L22: 50 | M22: 0 | N22: 45 | O22: 60 | P22: 40 | Q22: 45 | R22: 1500 | S22: 100 | T22: 80 | U22: 50 | W22: Plain FC6 write with no HMAC | X22: FAIL | Y22: HMAC_MISSING:command carried no HMAC signature | Z22: PASS | AA22: OK | AB22: DROP | AC22: HMAC_MISSING:command carried no HMAC signature | AD22: Missing HMAC (Unsigned Command) | AE22: ATTACK | AF22: =IF(OR(AE22="",C22=""),"",IF(C22="ATTACK",IF(AE22="ATTACK","TP","FN"),IF(AE22="ATTACK","FP","TN")))
A23: A02 | B23: Value tampered in transit | C23: ATTACK | D23: Tampered / Forged HMAC | E23: 127.0.0.1 | F23: 16 | G23: HEATER_TEMP | H23: 61 | I23: tampered | J23: 1 | K23: 12 | L23: 50 | M23: 0 | N23: 45 | O23: 60 | P23: 40 | Q23: 45 | R23: 1500 | S23: 100 | T23: 80 | U23: 50 | W23: Signed 61 C, value changed to 140 C, original tag kept | X23: FAIL | Y23: HMAC_INVALID:HMAC tag does not match command (tampered or wrong key) | Z23: FAIL | AA23: RATE_OF_CHANGE_EXCEEDED:HEATER_TEMP Δ80.00 > max 66.00 in 12.000s | AB23: DROP | AC23: HMAC_INVALID:HMAC tag does not match command (tampered or wrong key) | AD23: Tampered / Forged HMAC | AE23: ATTACK | AF23: =IF(OR(AE23="",C23=""),"",IF(C23="ATTACK",IF(AE23="ATTACK","TP","FN"),IF(AE23="ATTACK","FP","TN")))
A24: A03 | B24: Forged signature | C24: ATTACK | D24: Tampered / Forged HMAC | E24: 127.0.0.1 | F24: 16 | G24: COOLING_VALVE | H24: 46 | I24: wrong_key | J24: 1 | K24: 12 | L24: 50 | M24: 0 | N24: 45 | O24: 60 | P24: 40 | Q24: 45 | R24: 1500 | S24: 100 | T24: 80 | U24: 50 | W24: Signed with an attacker-chosen key | X24: FAIL | Y24: HMAC_INVALID:HMAC tag does not match command (tampered or wrong key) | Z24: PASS | AA24: OK | AB24: DROP | AC24: HMAC_INVALID:HMAC tag does not match command (tampered or wrong key) | AD24: Tampered / Forged HMAC | AE24: ATTACK | AF24: =IF(OR(AE24="",C24=""),"",IF(C24="ATTACK",IF(AE24="ATTACK","TP","FN"),IF(AE24="ATTACK","FP","TN")))
A25: A04 | B25: Delayed replay (expired) | C25: ATTACK | D25: Expired Signature (Delayed Replay) | E25: 127.0.0.1 | F25: 16 | G25: CONVEYOR_SPEED | H25: 2 | I25: expired | J25: 1 | K25: 12 | L25: 50 | M25: 0 | N25: 45 | O25: 60 | P25: 40 | Q25: 45 | R25: 1500 | S25: 100 | T25: 80 | U25: 50 | W25: Correct signature, timestamp 5 minutes old | X25: FAIL | Y25: HMAC_EXPIRED:signed timestamp outside +/-30s freshness window | Z25: PASS | AA25: OK | AB25: DROP | AC25: HMAC_EXPIRED:signed timestamp outside +/-30s freshness window | AD25: Expired Signature (Delayed Replay) | AE25: ATTACK | AF25: =IF(OR(AE25="",C25=""),"",IF(C25="ATTACK",IF(AE25="ATTACK","TP","FN"),IF(AE25="ATTACK","FP","TN")))
A26: A05 | B26: Immediate replay | C26: ATTACK | D26: Replay | E26: 127.0.0.1 | F26: 16 | G26: CONVEYOR_SPEED | H26: 2 | I26: replayed | J26: 1 | K26: 12 | L26: 50 | M26: 0 | N26: 45 | O26: 60 | P26: 40 | Q26: 45 | R26: 1500 | S26: 100 | T26: 80 | U26: 50 | W26: Byte-identical signed frame sent twice; second is evaluated | X26: FAIL | Y26: REPLAY_DETECTED:nonce reused | Z26: PASS | AA26: OK | AB26: DROP | AC26: REPLAY_DETECTED:nonce reused | AD26: Replay | AE26: ATTACK | AF26: =IF(OR(AE26="",C26=""),"",IF(C26="ATTACK",IF(AE26="ATTACK","TP","FN"),IF(AE26="ATTACK","FP","TN")))
A27: A06 | B27: Malformed signed frame | C27: ATTACK | D27: Malformed Signed Frame | E27: 127.0.0.1 | F27: 16 | G27: COOLING_VALVE | H27: 46 | I27: malformed | J27: 1 | K27: 12 | L27: 50 | M27: 0 | N27: 45 | O27: 60 | P27: 40 | Q27: 45 | R27: 1500 | S27: 100 | T27: 80 | U27: 50 | W27: Truncated HMAC tag | X27: FAIL | Y27: HMAC_MALFORMED:HMAC tag has wrong length | Z27: PASS | AA27: OK | AB27: DROP | AC27: HMAC_MALFORMED:HMAC tag has wrong length | AD27: Malformed Signed Frame | AE27: ATTACK | AF27: =IF(OR(AE27="",C27=""),"",IF(C27="ATTACK",IF(AE27="ATTACK","TP","FN"),IF(AE27="ATTACK","FP","TN")))
A28: A07 | B28: Rogue host with stolen key | C28: ATTACK | D28: Untrusted Source | E28: 10.0.0.99 | F28: 16 | G28: COOLING_VALVE | H28: 46 | I28: valid | J28: 1 | K28: 12 | L28: 50 | M28: 0 | N28: 45 | O28: 60 | P28: 40 | Q28: 45 | R28: 1500 | S28: 100 | T28: 80 | U28: 50 | W28: Valid signature but connection from a non-SCADA address | X28: FAIL | Y28: UNTRUSTED_SOURCE | Z28: PASS | AA28: OK | AB28: DROP | AC28: UNTRUSTED_SOURCE | AD28: Untrusted Source | AE28: ATTACK | AF28: =IF(OR(AE28="",C28=""),"",IF(C28="ATTACK",IF(AE28="ATTACK","TP","FN"),IF(AE28="ATTACK","FP","TN")))
A29: A08 | B29: Probe of unmapped register | C29: ATTACK | D29: Invalid Register Access | E29: 127.0.0.1 | F29: 16 | G29: 42 | H29: 10 | I29: valid | J29: 1 | K29: 12 | L29: 50 | M29: 0 | N29: 45 | O29: 60 | P29: 40 | Q29: 45 | R29: 1500 | S29: 100 | T29: 80 | U29: 50 | W29: Write to address 42 (no such machine) | X29: FAIL | Y29: INVALID_REGISTER | Z29: FAIL | AA29: UNKNOWN_REGISTER:42 | AB29: DROP | AC29: INVALID_REGISTER | AD29: Invalid Register Access | AE29: ATTACK | AF29: =IF(OR(AE29="",C29=""),"",IF(C29="ATTACK",IF(AE29="ATTACK","TP","FN"),IF(AE29="ATTACK","FP","TN")))
A30: A09 | B30: Invalid function code | C30: ATTACK | D30: Invalid Function Code | E30: 127.0.0.1 | F30: 5 | G30: CONVEYOR_SPEED | H30: 2 | I30: valid | J30: 1 | K30: 12 | L30: 50 | M30: 0 | N30: 45 | O30: 60 | P30: 40 | Q30: 45 | R30: 1500 | S30: 100 | T30: 80 | U30: 50 | W30: FC5 (write coil) against a holding register | X30: FAIL | Y30: INVALID_FUNCTION_CODE | Z30: PASS | AA30: OK | AB30: DROP | AC30: INVALID_FUNCTION_CODE | AD30: Invalid Function Code | AE30: ATTACK | AF30: =IF(OR(AE30="",C30=""),"",IF(C30="ATTACK",IF(AE30="ATTACK","TP","FN"),IF(AE30="ATTACK","FP","TN")))
A31: A10 | B31: Command flood | C31: ATTACK | D31: Flood / Rate Limit | E31: 127.0.0.1 | F31: 16 | G31: CONVEYOR_SPEED | H31: 2 | I31: valid | J31: 8 | K31: 12 | L31: 50 | M31: 0 | N31: 45 | O31: 60 | P31: 40 | Q31: 45 | R31: 1500 | S31: 100 | T31: 80 | U31: 50 | W31: 8 signed commands in < 1 s; last one evaluated | X31: FAIL | Y31: RATE_LIMIT_EXCEEDED | Z31: PASS | AA31: OK | AB31: DROP | AC31: RATE_LIMIT_EXCEEDED | AD31: Flood / Rate Limit | AE31: ATTACK | AF31: =IF(OR(AE31="",C31=""),"",IF(C31="ATTACK",IF(AE31="ATTACK","TP","FN"),IF(AE31="ATTACK","FP","TN")))
A32: A11 | B32: Impossible tank pressure | C32: ATTACK | D32: Impossible Command (Out of Bounds) | E32: 127.0.0.1 | F32: 16 | G32: TANK_PRESSURE | H32: 999 | I32: valid | J32: 1 | K32: 12 | L32: 50 | M32: 0 | N32: 45 | O32: 60 | P32: 40 | Q32: 45 | R32: 1500 | S32: 100 | T32: 80 | U32: 50 | X32: PASS | Y32: OK | Z32: FAIL | AA32: OUT_OF_BOUNDS:TANK_PRESSURE=999.00 (allowed 0–100) | AB32: DROP | AC32: OUT_OF_BOUNDS:TANK_PRESSURE=999.00 (allowed 0–100) | AD32: Impossible Command (Out of Bounds) | AE32: ATTACK | AF32: =IF(OR(AE32="",C32=""),"",IF(C32="ATTACK",IF(AE32="ATTACK","TP","FN"),IF(AE32="ATTACK","FP","TN")))
A33: A12 | B33: Impossible heater temperature | C33: ATTACK | D33: Impossible Command (Out of Bounds) | E33: 127.0.0.1 | F33: 16 | G33: HEATER_TEMP | H33: 180 | I33: valid | J33: 1 | K33: 12 | L33: 50 | M33: 0 | N33: 45 | O33: 60 | P33: 40 | Q33: 45 | R33: 1500 | S33: 100 | T33: 80 | U33: 50 | X33: PASS | Y33: OK | Z33: FAIL | AA33: OUT_OF_BOUNDS:HEATER_TEMP=180.00 (allowed 0–150) | AB33: DROP | AC33: OUT_OF_BOUNDS:HEATER_TEMP=180.00 (allowed 0–150) | AD33: Impossible Command (Out of Bounds) | AE33: ATTACK | AF33: =IF(OR(AE33="",C33=""),"",IF(C33="ATTACK",IF(AE33="ATTACK","TP","FN"),IF(AE33="ATTACK","FP","TN")))
A34: A13 | B34: Physically impossible ramp | C34: ATTACK | D34: Rate-of-Change Violation | E34: 127.0.0.1 | F34: 16 | G34: CONVEYOR_SPEED | H34: 100 | I34: valid | J34: 1 | K34: 0.2 | L34: 50 | M34: 0 | N34: 45 | O34: 60 | P34: 40 | Q34: 45 | R34: 1500 | S34: 100 | T34: 80 | U34: 50 | W34: 0 -> 100 RPM in 0.2 s | X34: PASS | Y34: OK | Z34: FAIL | AA34: RATE_OF_CHANGE_EXCEEDED:CONVEYOR_SPEED Δ100.00 > max 2.20 in 0.200s | AB34: DROP | AC34: RATE_OF_CHANGE_EXCEEDED:CONVEYOR_SPEED Δ100.00 > max 2.20 in 0.200s | AD34: Rate-of-Change Violation | AE34: ATTACK | AF34: =IF(OR(AE34="",C34=""),"",IF(C34="ATTACK",IF(AE34="ATTACK","TP","FN"),IF(AE34="ATTACK","FP","TN")))
A35: A14 | B35: Thermal runaway via heater | C35: ATTACK | D35: Cross-Register Correlation | E35: 127.0.0.1 | F35: 16 | G35: HEATER_TEMP | H35: 112 | I35: valid | J35: 1 | K35: 10 | L35: 50 | M35: 0 | N35: 20 | O35: 102 | P35: 40 | Q35: 45 | R35: 1500 | S35: 100 | T35: 80 | U35: 50 | W35: Each value safe alone; heater 112 + cooling 20 is unsafe | X35: PASS | Y35: OK | Z35: FAIL | AA35: CROSS_REGISTER_VIOLATION:THERMAL_RUNAWAY:HEATER_TEMP=112.0>=110 & COOLING_VALVE=20.0<=25 (heater setpoint high while cooling valve nearly closed - heat cannot be removed) | AB35: DROP | AC35: CROSS_REGISTER_VIOLATION:THERMAL_RUNAWAY:HEATER_TEMP=112.0>=110 & COOLING_VALVE=20.0<=25 (heater setpoint high while cooling valve nearly closed - heat cannot be removed) | AD35: Cross-Register Correlation | AE35: ATTACK | AF35: =IF(OR(AE35="",C35=""),"",IF(C35="ATTACK",IF(AE35="ATTACK","TP","FN"),IF(AE35="ATTACK","FP","TN")))
A36: A15 | B36: Thermal runaway via cooling valve | C36: ATTACK | D36: Cross-Register Correlation | E36: 127.0.0.1 | F36: 16 | G36: COOLING_VALVE | H36: 24 | I36: valid | J36: 1 | K36: 10 | L36: 50 | M36: 0 | N36: 30 | O36: 115 | P36: 40 | Q36: 45 | R36: 1500 | S36: 100 | T36: 80 | U36: 50 | X36: PASS | Y36: OK | Z36: FAIL | AA36: CROSS_REGISTER_VIOLATION:THERMAL_RUNAWAY:HEATER_TEMP=115.0>=110 & COOLING_VALVE=24.0<=25 (heater setpoint high while cooling valve nearly closed - heat cannot be removed) | AB36: DROP | AC36: CROSS_REGISTER_VIOLATION:THERMAL_RUNAWAY:HEATER_TEMP=115.0>=110 & COOLING_VALVE=24.0<=25 (heater setpoint high while cooling valve nearly closed - heat cannot be removed) | AD36: Cross-Register Correlation | AE36: ATTACK | AF36: =IF(OR(AE36="",C36=""),"",IF(C36="ATTACK",IF(AE36="ATTACK","TP","FN"),IF(AE36="ATTACK","FP","TN")))
A37: A16 | B37: Overpressure via feed pump | C37: ATTACK | D37: Cross-Register Correlation | E37: 127.0.0.1 | F37: 16 | G37: FEED_PUMP | H37: 75 | I37: valid | J37: 1 | K37: 10 | L37: 50 | M37: 0 | N37: 45 | O37: 60 | P37: 65 | Q37: 10 | R37: 1500 | S37: 100 | T37: 80 | U37: 50 | X37: PASS | Y37: OK | Z37: FAIL | AA37: CROSS_REGISTER_VIOLATION:OVERPRESSURE:FEED_PUMP=75.0>=70 & RELIEF_VALVE=10.0<=15 (feed pump driving flow into tank while relief valve nearly closed - tank cannot vent) | AB37: DROP | AC37: CROSS_REGISTER_VIOLATION:OVERPRESSURE:FEED_PUMP=75.0>=70 & RELIEF_VALVE=10.0<=15 (feed pump driving flow into tank while relief valve nearly closed - tank cannot vent) | AD37: Cross-Register Correlation | AE37: ATTACK | AF37: =IF(OR(AE37="",C37=""),"",IF(C37="ATTACK",IF(AE37="ATTACK","TP","FN"),IF(AE37="ATTACK","FP","TN")))
A38: A17 | B38: Overpressure via pending setpoint | C38: ATTACK | D38: Cross-Register Correlation | E38: 127.0.0.1 | F38: 16 | G38: FEED_PUMP | H38: 75 | I38: valid | J38: 1 | K38: 10 | L38: 50 | M38: 0 | N38: 45 | O38: 60 | P38: 65 | Q38: 40 | R38: 1500 | S38: 100 | T38: 80 | U38: 50 | V38: {"RELIEF_VALVE": 10.0} | W38: Relief telemetry still 40 but an approved setpoint of 10 is ramping | X38: PASS | Y38: OK | Z38: FAIL | AA38: CROSS_REGISTER_VIOLATION:OVERPRESSURE:FEED_PUMP=75.0>=70 & RELIEF_VALVE=10.0<=15 (feed pump driving flow into tank while relief valve nearly closed - tank cannot vent) | AB38: DROP | AC38: CROSS_REGISTER_VIOLATION:OVERPRESSURE:FEED_PUMP=75.0>=70 & RELIEF_VALVE=10.0<=15 (feed pump driving flow into tank while relief valve nearly closed - tank cannot vent) | AD38: Cross-Register Correlation | AE38: ATTACK | AF38: =IF(OR(AE38="",C38=""),"",IF(C38="ATTACK",IF(AE38="ATTACK","TP","FN"),IF(AE38="ATTACK","FP","TN")))
A39: A18 | B39: Hot pressurized vessel | C39: ATTACK | D39: Cross-Register Correlation | E39: 127.0.0.1 | F39: 16 | G39: TANK_PRESSURE | H39: 86 | I39: valid | J39: 1 | K39: 5 | L39: 80 | M39: 0 | N39: 45 | O39: 130 | P39: 40 | Q39: 45 | R39: 1500 | S39: 100 | T39: 80 | U39: 50 | X39: PASS | Y39: OK | Z39: FAIL | AA39: CROSS_REGISTER_VIOLATION:HOT_PRESSURIZED_VESSEL:TANK_PRESSURE=86.0>=85 & HEATER_TEMP=130.0>=125 (tank pressure and heater temperature both near limits at the same time) | AB39: DROP | AC39: CROSS_REGISTER_VIOLATION:HOT_PRESSURIZED_VESSEL:TANK_PRESSURE=86.0>=85 & HEATER_TEMP=130.0>=125 (tank pressure and heater temperature both near limits at the same time) | AD39: Cross-Register Correlation | AE39: ATTACK | AF39: =IF(OR(AE39="",C39=""),"",IF(C39="ATTACK",IF(AE39="ATTACK","TP","FN"),IF(AE39="ATTACK","FP","TN")))
A40: A19 | B40: Valve slam at low pressure | C40: ATTACK | D40: Cross-Register Correlation | E40: 127.0.0.1 | F40: 16 | G40: COOLING_VALVE | H40: 30 | I40: valid | J40: 1 | K40: 10 | L40: 8 | M40: 0 | N40: 60 | O40: 60 | P40: 40 | Q40: 45 | R40: 1500 | S40: 100 | T40: 80 | U40: 50 | X40: PASS | Y40: OK | Z40: FAIL | AA40: CROSS_REGISTER_VIOLATION:VALVE_CLOSING_LOW_PRESSURE:valve closing sharply with tank pressure already low | AB40: DROP | AC40: CROSS_REGISTER_VIOLATION:VALVE_CLOSING_LOW_PRESSURE:valve closing sharply with tank pressure already low | AD40: Cross-Register Correlation | AE40: ATTACK | AF40: =IF(OR(AE40="",C40=""),"",IF(C40="ATTACK",IF(AE40="ATTACK","TP","FN"),IF(AE40="ATTACK","FP","TN")))
A41: A20 | B41: Conveyor max at pressure limit | C41: ATTACK | D41: Cross-Register Correlation | E41: 127.0.0.1 | F41: 16 | G41: CONVEYOR_SPEED | H41: 110 | I41: valid | J41: 1 | K41: 5 | L41: 95 | M41: 100 | N41: 45 | O41: 60 | P41: 40 | Q41: 45 | R41: 1500 | S41: 100 | T41: 80 | U41: 50 | X41: PASS | Y41: OK | Z41: FAIL | AA41: CROSS_REGISTER_VIOLATION:CONVEYOR_PRESSURE_OVERLOAD:conveyor near max speed while tank pressure near limit | AB41: DROP | AC41: CROSS_REGISTER_VIOLATION:CONVEYOR_PRESSURE_OVERLOAD:conveyor near max speed while tank pressure near limit | AD41: Cross-Register Correlation | AE41: ATTACK | AF41: =IF(OR(AE41="",C41=""),"",IF(C41="ATTACK",IF(AE41="ATTACK","TP","FN"),IF(AE41="ATTACK","FP","TN")))
...

Sheet Results
A1: Industrial Mind - System Efficiency Results
A2: Evaluated 2026-10-01T16:09:10 over TestCases rows 2-47. Positive class = ATTACK. Formulas recalculate from TestCases.
A4: Metric | B4: Value (Excel formula) | C4: Value (evaluate_system.py) | D4: Check | E4: Definition
A5: Total Cases | B5: =COUNTIF(TestCases!$C$2:$C$47,"ATTACK")+COUNTIF(TestCases!$C$2:$C$47,"NORMAL") | C5: 46 | D5: =IF(ABS(B5-C5)<0.000001,"OK","MISMATCH") | E5: labelled cases
A6: Actual Attacks | B6: =COUNTIF(TestCases!$C$2:$C$47,"ATTACK") | C6: 24 | D6: =IF(ABS(B6-C6)<0.000001,"OK","MISMATCH") | E6: Actual Label = ATTACK
A7: Actual Normal | B7: =COUNTIF(TestCases!$C$2:$C$47,"NORMAL") | C7: 22 | D7: =IF(ABS(B7-C7)<0.000001,"OK","MISMATCH") | E7: Actual Label = NORMAL
A8: TP | B8: =COUNTIFS(TestCases!$C$2:$C$47,"ATTACK",TestCases!$AE$2:$AE$47,"ATTACK") | C8: 22 | D8: =IF(ABS(B8-C8)<0.000001,"OK","MISMATCH") | E8: attack correctly dropped
A9: TN | B9: =COUNTIFS(TestCases!$C$2:$C$47,"NORMAL",TestCases!$AE$2:$AE$47,"NORMAL") | C9: 21 | D9: =IF(ABS(B9-C9)<0.000001,"OK","MISMATCH") | E9: normal command correctly passed
A10: FP | B10: =COUNTIFS(TestCases!$C$2:$C$47,"NORMAL",TestCases!$AE$2:$AE$47,"ATTACK") | C10: 1 | D10: =IF(ABS(B10-C10)<0.000001,"OK","MISMATCH") | E10: normal command wrongly dropped
A11: FN | B11: =COUNTIFS(TestCases!$C$2:$C$47,"ATTACK",TestCases!$AE$2:$AE$47,"NORMAL") | C11: 2 | D11: =IF(ABS(B11-C11)<0.000001,"OK","MISMATCH") | E11: attack wrongly passed
A12: Accuracy | B12: =IFERROR((B8+B9)/(B8+B9+B10+B11),0) | C12: 0.93478261 | D12: =IF(ABS(B12-C12)<0.000001,"OK","MISMATCH") | E12: (TP+TN)/(TP+TN+FP+FN)
A13: Precision | B13: =IFERROR(B8/(B8+B10),0) | C13: 0.95652174 | D13: =IF(ABS(B13-C13)<0.000001,"OK","MISMATCH") | E13: TP/(TP+FP)
A14: Recall | B14: =IFERROR(B8/(B8+B11),0) | C14: 0.91666667 | D14: =IF(ABS(B14-C14)<0.000001,"OK","MISMATCH") | E14: TP/(TP+FN)
A15: F1-score | B15: =IFERROR(2*B13*B14/(B13+B14),0) | C15: 0.93617021 | D15: =IF(ABS(B15-C15)<0.000001,"OK","MISMATCH") | E15: 2*Precision*Recall/(Precision+Recall)
A16: Detection Rate | B16: =IFERROR(B8/(B8+B11),0) | C16: 0.91666667 | D16: =IF(ABS(B16-C16)<0.000001,"OK","MISMATCH") | E16: attacks detected / all attacks (= Recall)
A17: False Positive Rate | B17: =IFERROR(B10/(B10+B9),0) | C17: 0.045454545 | D17: =IF(ABS(B17-C17)<0.000001,"OK","MISMATCH") | E17: FP/(FP+TN)
A18: Specificity | B18: =IFERROR(B9/(B9+B10),0) | C18: 0.95454545 | D18: =IF(ABS(B18-C18)<0.000001,"OK","MISMATCH") | E18: TN/(TN+FP)
A20: Detection by attack type
A21: Expected Attack Type | B21: Attack Cases | C21: Detected (DROP) | D21: Detection Rate
A22: Cross-Register Correlation | B22: =COUNTIFS(TestCases!$D$2:$D$47,A22,TestCases!$C$2:$C$47,"ATTACK") | C22: =COUNTIFS(TestCases!$D$2:$D$47,A22,TestCases!$C$2:$C$47,"ATTACK",TestCases!$AE$2:$AE$47,"ATTACK") | D22: =IFERROR(C22/B22,0)
A23: Expired Signature (Delayed Replay) | B23: =COUNTIFS(TestCases!$D$2:$D$47,A23,TestCases!$C$2:$C$47,"ATTACK") | C23: =COUNTIFS(TestCases!$D$2:$D$47,A23,TestCases!$C$2:$C$47,"ATTACK",TestCases!$AE$2:$AE$47,"ATTACK") | D23: =IFERROR(C23/B23,0)
A24: Flood / Rate Limit | B24: =COUNTIFS(TestCases!$D$2:$D$47,A24,TestCases!$C$2:$C$47,"ATTACK") | C24: =COUNTIFS(TestCases!$D$2:$D$47,A24,TestCases!$C$2:$C$47,"ATTACK",TestCases!$AE$2:$AE$47,"ATTACK") | D24: =IFERROR(C24/B24,0)
A25: Impossible Command (Out of Bounds) | B25: =COUNTIFS(TestCases!$D$2:$D$47,A25,TestCases!$C$2:$C$47,"ATTACK") | C25: =COUNTIFS(TestCases!$D$2:$D$47,A25,TestCases!$C$2:$C$47,"ATTACK",TestCases!$AE$2:$AE$47,"ATTACK") | D25: =IFERROR(C25/B25,0)
A26: Invalid Function Code | B26: =COUNTIFS(TestCases!$D$2:$D$47,A26,TestCases!$C$2:$C$47,"ATTACK") | C26: =COUNTIFS(TestCases!$D$2:$D$47,A26,TestCases!$C$2:$C$47,"ATTACK",TestCases!$AE$2:$AE$47,"ATTACK") | D26: =IFERROR(C26/B26,0)
A27: Invalid Register Access | B27: =COUNTIFS(TestCases!$D$2:$D$47,A27,TestCases!$C$2:$C$47,"ATTACK") | C27: =COUNTIFS(TestCases!$D$2:$D$47,A27,TestCases!$C$2:$C$47,"ATTACK",TestCases!$AE$2:$AE$47,"ATTACK") | D27: =IFERROR(C27/B27,0)
A28: Malformed Signed Frame | B28: =COUNTIFS(TestCases!$D$2:$D$47,A28,TestCases!$C$2:$C$47,"ATTACK") | C28: =COUNTIFS(TestCases!$D$2:$D$47,A28,TestCases!$C$2:$C$47,"ATTACK",TestCases!$AE$2:$AE$47,"ATTACK") | D28: =IFERROR(C28/B28,0)
A29: Missing HMAC (Unsigned Command) | B29: =COUNTIFS(TestCases!$D$2:$D$47,A29,TestCases!$C$2:$C$47,"ATTACK") | C29: =COUNTIFS(TestCases!$D$2:$D$47,A29,TestCases!$C$2:$C$47,"ATTACK",TestCases!$AE$2:$AE$47,"ATTACK") | D29: =IFERROR(C29/B29,0)
A30: Rate-of-Change Violation | B30: =COUNTIFS(TestCases!$D$2:$D$47,A30,TestCases!$C$2:$C$47,"ATTACK") | C30: =COUNTIFS(TestCases!$D$2:$D$47,A30,TestCases!$C$2:$C$47,"ATTACK",TestCases!$AE$2:$AE$47,"ATTACK") | D30: =IFERROR(C30/B30,0)
A31: Replay | B31: =COUNTIFS(TestCases!$D$2:$D$47,A31,TestCases!$C$2:$C$47,"ATTACK") | C31: =COUNTIFS(TestCases!$D$2:$D$47,A31,TestCases!$C$2:$C$47,"ATTACK",TestCases!$AE$2:$AE$47,"ATTACK") | D31: =IFERROR(C31/B31,0)
A32: Stealthy In-Bounds Manipulation | B32: =COUNTIFS(TestCases!$D$2:$D$47,A32,TestCases!$C$2:$C$47,"ATTACK") | C32: =COUNTIFS(TestCases!$D$2:$D$47,A32,TestCases!$C$2:$C$47,"ATTACK",TestCases!$AE$2:$AE$47,"ATTACK") | D32: =IFERROR(C32/B32,0)
A33: Tampered / Forged HMAC | B33: =COUNTIFS(TestCases!$D$2:$D$47,A33,TestCases!$C$2:$C$47,"ATTACK") | C33: =COUNTIFS(TestCases!$D$2:$D$47,A33,TestCases!$C$2:$C$47,"ATTACK",TestCases!$AE$2:$AE$47,"ATTACK") | D33: =IFERROR(C33/B33,0)
A34: Untrusted Source | B34: =COUNTIFS(TestCases!$D$2:$D$47,A34,TestCases!$C$2:$C$47,"ATTACK") | C34: =COUNTIFS(TestCases!$D$2:$D$47,A34,TestCases!$C$2:$C$47,"ATTACK",TestCases!$AE$2:$AE$47,"ATTACK") | D34: =IFERROR(C34/B34,0)

Sheet Confusion Matrix
A1: Confusion Matrix (positive class = ATTACK)
A3: Actual \ Predicted | B3: Predicted ATTACK | C3: Predicted NORMAL | D3: Total
A4: Actual ATTACK | B4: =Results!B8 | C4: =Results!B11 | D4: =B4+C4
A5: Actual NORMAL | B5: =Results!B10 | C5: =Results!B9 | D5: =B5+C5
A6: Total | B6: =B4+B5 | C6: =C4+C5 | D6: =D4+D5
A8: TP = Actual ATTACK & Predicted ATTACK · FN = Actual ATTACK & Predicted NORMAL · FP = Actual NORMAL & Predicted ATTACK · TN = Actual NORMAL & Predicted NORMAL

Sheet README
A1: Industrial Mind - System Efficiency Test Data
A3: Blue columns (TestCases A..W) are INPUTS you may edit or extend with new rows.
A4: Green columns are OUTPUTS written by evaluation/evaluate_system.py - do not edit by hand.
A5: Actual Label is the ground truth: NORMAL or ATTACK. Positive class = ATTACK.
A6: Predicted Label = ATTACK when the real Orchestrator decision is DROP, NORMAL when PASS.
A8: Column meanings
A9: Machine Register: machine name from docs/interfaces.MACHINES (e.g. HEATER_TEMP) or a raw address number.
A10: Signature Mode: valid | missing | tampered | wrong_key | expired | replayed | malformed.
A11: Repeat Count: number of back-to-back sends from the same source; the LAST one is evaluated (flood tests).
A12: Seconds Since Last Settle: time the register has had to move since it last settled (rate-of-change check).
A13: Current <MACHINE>: live PLC telemetry for each machine when the command arrives.
A14: Pending Setpoints (JSON): approved targets still ramping, e.g. {"RELIEF_VALVE": 10}.
... A20: Results and Confusion Matrix sheets are rebuilt with Excel formulas over TestCases on every run.
